2018-07-17 21:25:05,050 - teradata.udaexec - INFO - Initializing UdaExec...
2018-07-17 21:25:05,050 - teradata.udaexec - INFO - Reading config files: ['C:\\etc\\udaexec.ini: Not Found', 'C:\\Users\\sngobese\\udaexec.ini: Not Found', 'C:\\Users\\sngobese\\Documents\\Internet_of_Things\\udaexec.ini: Not Found']
2018-07-17 21:25:05,050 - teradata.udaexec - INFO - Found run number file: "C:\Users\sngobese\Documents\Internet_of_Things\.runNumber"
2018-07-17 21:25:05,050 - teradata.udaexec - INFO - Cleaning up log files older than 90 days.
2018-07-17 21:25:05,050 - teradata.udaexec - INFO - Removed 0 log files.
2018-07-17 21:25:05,142 - teradata.udaexec - INFO - Checkpoint file not found: C:\Users\sngobese\Documents\Internet_of_Things\TestAPP.checkpoint
2018-07-17 21:25:05,142 - teradata.udaexec - INFO - No previous checkpoint found, executing from beginning...
2018-07-17 21:25:05,142 - teradata.udaexec - INFO - Execution Details:
/********************************************************************************
 * Application Name: TestAPP
 *          Version: 1.0
 *       Run Number: 20180717212505-4
 *             Host: NB-SNGOBESE
 *         Platform: Windows-10-10.0.16299-SP0
 *          OS User: SNgobese
 *   Python Version: 3.5.2
 *  Python Compiler: MSC v.1900 64 bit (AMD64)
 *     Python Build: ('v3.5.2:4def2a2901a5', 'Jun 25 2016 22:18:55')
 *  UdaExec Version: 15.10.0.21
 *     Program Name: C:\Users\sngobese\AppData\Local\Programs\Python\Python35\lib\site-packages\ipykernel_launcher.py
 *      Working Dir: C:\Users\sngobese\Documents\Internet_of_Things
 *          Log Dir: C:\Users\sngobese\Documents\Internet_of_Things\logs
 *         Log File: C:\Users\sngobese\Documents\Internet_of_Things\logs\TestAPP.20180717212505-4.log
 *     Config Files: ['C:\\etc\\udaexec.ini: Not Found', 'C:\\Users\\sngobese\\udaexec.ini: Not Found', 'C:\\Users\\sngobese\\Documents\\Internet_of_Things\\udaexec.ini: Not Found']
 *      Query Bands: ApplicationName=TestAPP;Version=1.0;JobID=20180717212505-4;ClientUser=SNgobese;Production=False;udaAppLogFile=C:\Users\sngobese\Documents\Internet_of_Things\logs\TestAPP.20180717212505-4.log;UtilityName=PyTd;UtilityVersion=15.10.0.21
********************************************************************************/
2018-07-17 21:25:05,143 - teradata.udaexec - INFO - Creating connection: {'method': 'odbc', 'username': 'dbc', 'password': 'XXXXXX', 'dsn': 'teradata'}
2018-07-17 21:25:05,146 - teradata.tdodbc - INFO - Available drivers: SQL Server, SQL Server Native Client 10.0, MySQL ODBC 5.3 ANSI Driver, MySQL ODBC 5.3 Unicode Driver, PostgreSQL ANSI(x64), PostgreSQL Unicode(x64), Amazon Redshift (x64), Teradata Database ODBC Driver 16.20
2018-07-17 21:25:06,466 - teradata.udaexec - INFO - Connection successful. Duration: 1.322 seconds. Details: {'method': 'odbc', 'username': 'dbc', 'password': 'XXXXXX', 'dsn': 'teradata'}
2018-07-17 21:27:01,209 - teradata.udaexec - ERROR - Query Failed! Duration: 0.004 seconds, Query: CALL tdata_db_2.Weather_Log_Create(6, 6)
Traceback (most recent call last):
  File "C:\Users\sngobese\AppData\Local\Programs\Python\Python35\lib\site-packages\teradata\udaexec.py", line 790, in _execute
    func(query, params, **kwargs)
  File "C:\Users\sngobese\AppData\Local\Programs\Python\Python35\lib\site-packages\teradata\tdodbc.py", line 614, in execute
    checkStatus(rc, hStmt=self.hStmt, method="SQLExecDirectW")
  File "C:\Users\sngobese\AppData\Local\Programs\Python\Python35\lib\site-packages\teradata\tdodbc.py", line 231, in checkStatus
    raise DatabaseError(i[2], u"[{}] {}".format(i[0], msg), i[0])
teradata.api.DatabaseError: (3802, "[42S02] [Teradata][ODBC Teradata Driver][Teradata Database](-3802)Database 'MYDB' does not exist., [Teradata][ODBC Teradata Driver][Teradata Database](-5510)Invalid session mode for procedure execution.")
