2018-07-18 15:06:45,940 - teradata.udaexec - INFO - Initializing UdaExec...
2018-07-18 15:06:45,940 - teradata.udaexec - INFO - Reading config files: ['C:\\etc\\udaexec.ini: Not Found', 'C:\\Users\\pphahlamohlaka\\udaexec.ini: Not Found', 'C:\\Users\\pphahlamohlaka\\Desktop\\IOT\\IoT\\udaexec.ini: Not Found']
2018-07-18 15:06:45,940 - teradata.udaexec - INFO - Found run number file: "C:\Users\pphahlamohlaka\Desktop\IOT\IoT\.runNumber"
2018-07-18 15:06:45,941 - teradata.udaexec - INFO - Cleaning up log files older than 90 days.
2018-07-18 15:06:45,941 - teradata.udaexec - INFO - Removed 0 log files.
2018-07-18 15:06:45,942 - teradata.udaexec - INFO - Checkpoint file not found: C:\Users\pphahlamohlaka\Desktop\IOT\IoT\TestAPP.checkpoint
2018-07-18 15:06:45,942 - teradata.udaexec - INFO - No previous checkpoint found, executing from beginning...
2018-07-18 15:06:45,942 - teradata.udaexec - INFO - Execution Details:
/********************************************************************************
 * Application Name: TestAPP
 *          Version: 1.0
 *       Run Number: 20180718150645-3
 *             Host: NB-PPROMISE
 *         Platform: Windows-10-10.0.16299-SP0
 *          OS User: PPhahlamohlaka
 *   Python Version: 3.6.5
 *  Python Compiler: MSC v.1900 64 bit (AMD64)
 *     Python Build: ('default', 'Mar 29 2018 13:32:41')
 *  UdaExec Version: 15.10.0.21
 *     Program Name: wcl.py
 *      Working Dir: C:\Users\pphahlamohlaka\Desktop\IOT\IoT
 *          Log Dir: C:\Users\pphahlamohlaka\Desktop\IOT\IoT\logs
 *         Log File: C:\Users\pphahlamohlaka\Desktop\IOT\IoT\logs\TestAPP.20180718150645-3.log
 *     Config Files: ['C:\\etc\\udaexec.ini: Not Found', 'C:\\Users\\pphahlamohlaka\\udaexec.ini: Not Found', 'C:\\Users\\pphahlamohlaka\\Desktop\\IOT\\IoT\\udaexec.ini: Not Found']
 *      Query Bands: ApplicationName=TestAPP;Version=1.0;JobID=20180718150645-3;ClientUser=PPhahlamohlaka;Production=False;udaAppLogFile=C:\Users\pphahlamohlaka\Desktop\IOT\IoT\logs\TestAPP.20180718150645-3.log;UtilityName=PyTd;UtilityVersion=15.10.0.21
********************************************************************************/
2018-07-18 15:06:45,942 - teradata.udaexec - INFO - Creating connection: {'method': 'odbc', 'dsn': 'teradata', 'username': 'dbc', 'password': 'XXXXXX'}
2018-07-18 15:06:45,951 - teradata.tdodbc - INFO - Available drivers: SQL Server, SQL Server Native Client 10.0, PostgreSQL ANSI(x64), PostgreSQL Unicode(x64), SQL Server Native Client 11.0, MySQL ODBC 5.3 ANSI Driver, MySQL ODBC 5.3 Unicode Driver, DataDirect 7.1 DB2 Wire Protocol, DataDirect 7.1 Informix Wire Protocol, DataDirect 7.1 Sybase Wire Protocol, DataDirect 7.1 SQL Server Wire Protocol, DataDirect 7.1 dBaseFile, DataDirect 7.1 FoxPro 3.0, DataDirect 7.1 MySQL Wire Protocol, DataDirect 7.1 New SQL Server Wire Protocol, DataDirect 7.1 Greenplum Wire Protocol, Informatica MongoDB ODBC Driver, DataDirect 7.1 Oracle Wire Protocol, Informatica Cassandra ODBC Driver, Informatica Data Services ODBC Driver 10.2.0, ODBC Driver 13 for SQL Server, Oracle in XE, Teradata Database ODBC Driver 16.20
2018-07-18 15:06:47,274 - teradata.udaexec - INFO - Connection successful. Duration: 1.328 seconds. Details: {'method': 'odbc', 'dsn': 'teradata', 'username': 'dbc', 'password': 'XXXXXX'}
2018-07-18 15:07:00,498 - teradata.udaexec - ERROR - Uncaught exception
Traceback (most recent call last):
  File "wcl.py", line 21, in <module>
    with urllib.request.urlopen(url) as response:
  File "C:\Users\pphahlamohlaka\AppData\Local\Continuum\anaconda3\lib\urllib\request.py", line 223, in urlopen
    return opener.open(url, data, timeout)
  File "C:\Users\pphahlamohlaka\AppData\Local\Continuum\anaconda3\lib\urllib\request.py", line 526, in open
    response = self._open(req, data)
  File "C:\Users\pphahlamohlaka\AppData\Local\Continuum\anaconda3\lib\urllib\request.py", line 544, in _open
    '_open', req)
  File "C:\Users\pphahlamohlaka\AppData\Local\Continuum\anaconda3\lib\urllib\request.py", line 504, in _call_chain
    result = func(*args)
  File "C:\Users\pphahlamohlaka\AppData\Local\Continuum\anaconda3\lib\urllib\request.py", line 1346, in http_open
    return self.do_open(http.client.HTTPConnection, req)
  File "C:\Users\pphahlamohlaka\AppData\Local\Continuum\anaconda3\lib\urllib\request.py", line 1321, in do_open
    r = h.getresponse()
  File "C:\Users\pphahlamohlaka\AppData\Local\Continuum\anaconda3\lib\http\client.py", line 1331, in getresponse
    response.begin()
  File "C:\Users\pphahlamohlaka\AppData\Local\Continuum\anaconda3\lib\http\client.py", line 297, in begin
    version, status, reason = self._read_status()
  File "C:\Users\pphahlamohlaka\AppData\Local\Continuum\anaconda3\lib\http\client.py", line 258, in _read_status
    line = str(self.fp.readline(_MAXLINE + 1), "iso-8859-1")
  File "C:\Users\pphahlamohlaka\AppData\Local\Continuum\anaconda3\lib\socket.py", line 586, in readinto
    return self._sock.recv_into(b)
KeyboardInterrupt
2018-07-18 15:07:00,516 - teradata.tdodbc - WARNING - 1 open connections found on exit, attempting to close...
2018-07-18 15:07:00,583 - teradata.udaexec - INFO - UdaExec exiting.
